Workbook

Sheet Premissas
A1: MODELO ECONÔMICO — REDE DE LAVAGEM AUTOMATIZADA POR ASSINATURA
A2: Reconstrução a partir dos números-resumo do Plano de Franquia (set/2026). O Excel original não foi fornecido.
A3: Células azuis são premissas editáveis. Tudo o mais é fórmula.
A5: PREMISSAS COMUNS
A6: Taxa mínima de atratividade (a.a.) | B6: 0.18
A7: Imposto sobre receita da unidade (Simples, efetivo) | B7: 0.11
A8: Custos variáveis (água, energia, química, gateway) | B8: 0.22
A9: Royalty sobre receita bruta | B9: 0.06
A10: Fundo de marketing sobre receita bruta | B10: 0.02
A11: Taxa de tecnologia (R$/mês por unidade) | B11: 700
A12: Capex de manutenção (% da receita) | B12: 0.015
A13: Valor residual no mês 60 (% do capex) | B13: 0.35
A14: Imposto sobre receita da franqueadora | B14: 0.16
A15: Rebate do fabricante por unidade instalada | B15: 25000
A17: PREMISSAS POR FORMATO
B18: BOX | C18: EXPRESS | D18: PRIME
A19: Taxa de franquia | B19: 35000 | C19: 50000 | D19: 60000
A20: Capex de instalação | B20: 155000 | C20: 326000 | D20: 600000
A21: Capital de giro | B21: 25000 | C21: 40000 | D21: 60000
A22: Receita madura (R$/mês) | B22: 19000 | C22: 48000 | D22: 75000
A23: EBITDA maduro informado no plano | B23: 5000 | C23: 15600 | D23: 24800
A24: Investimento total (taxa + capex + giro) | B24: =B19+B20+B21 | C24: =C19+C20+C21 | D24: =D19+D20+D21
A25: Custo fixo mensal (calibrado para reproduzir o EBITDA) | B25: =B22*(1-Premissas!$B$7-Premissas!$B$8-Premissas!$B$9-Premissas!$B$10)-Premissas!$B$11-B23 | C25: =C22*(1-Premissas!$B$7-Premissas!$B$8-Premissas!$B$9-Premissas!$B$10)-Premissas!$B$11-C23 | D25: =D22*(1-Premissas!$B$7-Premissas!$B$8-Premissas!$B$9-Premissas!$B$10)-Premissas!$B$11-D23
A27: CURVA DE MATURAÇÃO (% da receita madura)
A28: Meses 1–3 | B28: 0.35
A29: Meses 4–6 | B29: 0.55
A30: Meses 7–9 | B30: 0.75
A31: Meses 10–12 | B31: 0.88
A32: Mês 13 em diante | B32: 1

Sheet Resumo
A1: RESUMO EXECUTIVO
A2: Todos os valores vêm das abas de cálculo. Mude as premissas e tudo se move.
A4: FRANQUEADO
B5: BOX | C5: EXPRESS | D5: PRIME
A6: Investimento total | B6: =Box!B71 | C6: =Express!B71 | D6: =Prime!B71
A7: EBITDA maduro (R$/mês) | B7: =Box!B72 | C7: =Express!B72 | D7: =Prime!B72
A8: Margem EBITDA | B8: =Box!B73 | C8: =Express!B73 | D8: =Prime!B73
A9: Payback (meses) | B9: =Box!B74 | C9: =Express!B74 | D9: =Prime!B74
A10: TIR (a.a.) | B10: =Box!B76 | C10: =Express!B76 | D10: =Prime!B76
A11: VPL @ TMA | B11: =Box!B77 | C11: =Express!B77 | D11: =Prime!B77
A12: ROI 5 anos | B12: =Box!B78 | C12: =Express!B78 | D12: =Prime!B78
A14: LEITURA
A15: O formato BOX rende abaixo da TMA: VPL negativo. A recomendação do BP é retirá-lo da oferta.
A16: EXPRESS é o produto principal; PRIME só depois de validado em praça turística.

Sheet Box
A1: UNIDADE BOX — FLUXO MENSAL (60 MESES)
A3: Mês | B3: % rampa | C3: Receita | D3: Impostos | E3: Variáveis | F3: Royalty | G3: Fundo | H3: Tecnologia | I3: Fixos | J3: EBITDA | K3: Fluxo livre | L3: Acumulado
A4: 0 | K4: =-Premissas!B24 | L4: =-Premissas!B24
A5: 1 | B5: =IF(A5<=3,Premissas!$B$28,IF(A5<=6,Premissas!$B$29,IF(A5<=9,Premissas!$B$30,IF(A5<=12,Premissas!$B$31,Premissas!$B$32)))) | C5: =Premissas!B22*B5 | D5: =-C5*Premissas!$B$7 | E5: =-C5*Premissas!$B$8 | F5: =-C5*Premissas!$B$9 | G5: =-C5*Premissas!$B$10 | H5: =-Premissas!$B$11 | I5: =-Premissas!B25 | J5: =SUM(C5:I5) | K5: =J5-C5*Premissas!$B$12 | L5: =L4+K5
A6: 2 | B6: =IF(A6<=3,Premissas!$B$28,IF(A6<=6,Premissas!$B$29,IF(A6<=9,Premissas!$B$30,IF(A6<=12,Premissas!$B$31,Premissas!$B$32)))) | C6: =Premissas!B22*B6 | D6: =-C6*Premissas!$B$7 | E6: =-C6*Premissas!$B$8 | F6: =-C6*Premissas!$B$9 | G6: =-C6*Premissas!$B$10 | H6: =-Premissas!$B$11 | I6: =-Premissas!B25 | J6: =SUM(C6:I6) | K6: =J6-C6*Premissas!$B$12 | L6: =L5+K6
A7: 3 | B7: =IF(A7<=3,Premissas!$B$28,IF(A7<=6,Premissas!$B$29,IF(A7<=9,Premissas!$B$30,IF(A7<=12,Premissas!$B$31,Premissas!$B$32)))) | C7: =Premissas!B22*B7 | D7: =-C7*Premissas!$B$7 | E7: =-C7*Premissas!$B$8 | F7: =-C7*Premissas!$B$9 | G7: =-C7*Premissas!$B$10 | H7: =-Premissas!$B$11 | I7: =-Premissas!B25 | J7: =SUM(C7:I7) | K7: =J7-C7*Premissas!$B$12 | L7: =L6+K7
A8: 4 | B8: =IF(A8<=3,Premissas!$B$28,IF(A8<=6,Premissas!$B$29,IF(A8<=9,Premissas!$B$30,IF(A8<=12,Premissas!$B$31,Premissas!$B$32)))) | C8: =Premissas!B22*B8 | D8: =-C8*Premissas!$B$7 | E8: =-C8*Premissas!$B$8 | F8: =-C8*Premissas!$B$9 | G8: =-C8*Premissas!$B$10 | H8: =-Premissas!$B$11 | I8: =-Premissas!B25 | J8: =SUM(C8:I8) | K8: =J8-C8*Premissas!$B$12 | L8: =L7+K8
A9: 5 | B9: =IF(A9<=3,Premissas!$B$28,IF(A9<=6,Premissas!$B$29,IF(A9<=9,Premissas!$B$30,IF(A9<=12,Premissas!$B$31,Premissas!$B$32)))) | C9: =Premissas!B22*B9 | D9: =-C9*Premissas!$B$7 | E9: =-C9*Premissas!$B$8 | F9: =-C9*Premissas!$B$9 | G9: =-C9*Premissas!$B$10 | H9: =-Premissas!$B$11 | I9: =-Premissas!B25 | J9: =SUM(C9:I9) | K9: =J9-C9*Premissas!$B$12 | L9: =L8+K9
A10: 6 | B10: =IF(A10<=3,Premissas!$B$28,IF(A10<=6,Premissas!$B$29,IF(A10<=9,Premissas!$B$30,IF(A10<=12,Premissas!$B$31,Premissas!$B$32)))) | C10: =Premissas!B22*B10 | D10: =-C10*Premissas!$B$7 | E10: =-C10*Premissas!$B$8 | F10: =-C10*Premissas!$B$9 | G10: =-C10*Premissas!$B$10 | H10: =-Premissas!$B$11 | I10: =-Premissas!B25 | J10: =SUM(C10:I10) | K10: =J10-C10*Premissas!$B$12 | L10: =L9+K10
A11: 7 | B11: =IF(A11<=3,Premissas!$B$28,IF(A11<=6,Premissas!$B$29,IF(A11<=9,Premissas!$B$30,IF(A11<=12,Premissas!$B$31,Premissas!$B$32)))) | C11: =Premissas!B22*B11 | D11: =-C11*Premissas!$B$7 | E11: =-C11*Premissas!$B$8 | F11: =-C11*Premissas!$B$9 | G11: =-C11*Premissas!$B$10 | H11: =-Premissas!$B$11 | I11: =-Premissas!B25 | J11: =SUM(C11:I11) | K11: =J11-C11*Premissas!$B$12 | L11: =L10+K11
A12: 8 | B12: =IF(A12<=3,Premissas!$B$28,IF(A12<=6,Premissas!$B$29,IF(A12<=9,Premissas!$B$30,IF(A12<=12,Premissas!$B$31,Premissas!$B$32)))) | C12: =Premissas!B22*B12 | D12: =-C12*Premissas!$B$7 | E12: =-C12*Premissas!$B$8 | F12: =-C12*Premissas!$B$9 | G12: =-C12*Premissas!$B$10 | H12: =-Premissas!$B$11 | I12: =-Premissas!B25 | J12: =SUM(C12:I12) | K12: =J12-C12*Premissas!$B$12 | L12: =L11+K12
A13: 9 | B13: =IF(A13<=3,Premissas!$B$28,IF(A13<=6,Premissas!$B$29,IF(A13<=9,Premissas!$B$30,IF(A13<=12,Premissas!$B$31,Premissas!$B$32)))) | C13: =Premissas!B22*B13 | D13: =-C13*Premissas!$B$7 | E13: =-C13*Premissas!$B$8 | F13: =-C13*Premissas!$B$9 | G13: =-C13*Premissas!$B$10 | H13: =-Premissas!$B$11 | I13: =-Premissas!B25 | J13: =SUM(C13:I13) | K13: =J13-C13*Premissas!$B$12 | L13: =L12+K13
A14: 10 | B14: =IF(A14<=3,Premissas!$B$28,IF(A14<=6,Premissas!$B$29,IF(A14<=9,Premissas!$B$30,IF(A14<=12,Premissas!$B$31,Premissas!$B$32)))) | C14: =Premissas!B22*B14 | D14: =-C14*Premissas!$B$7 | E14: =-C14*Premissas!$B$8 | F14: =-C14*Premissas!$B$9 | G14: =-C14*Premissas!$B$10 | H14: =-Premissas!$B$11 | I14: =-Premissas!B25 | J14: =SUM(C14:I14) | K14: =J14-C14*Premissas!$B$12 | L14: =L13+K14
A15: 11 | B15: =IF(A15<=3,Premissas!$B$28,IF(A15<=6,Premissas!$B$29,IF(A15<=9,Premissas!$B$30,IF(A15<=12,Premissas!$B$31,Premissas!$B$32)))) | C15: =Premissas!B22*B15 | D15: =-C15*Premissas!$B$7 | E15: =-C15*Premissas!$B$8 | F15: =-C15*Premissas!$B$9 | G15: =-C15*Premissas!$B$10 | H15: =-Premissas!$B$11 | I15: =-Premissas!B25 | J15: =SUM(C15:I15) | K15: =J15-C15*Premissas!$B$12 | L15: =L14+K15
A16: 12 | B16: =IF(A16<=3,Premissas!$B$28,IF(A16<=6,Premissas!$B$29,IF(A16<=9,Premissas!$B$30,IF(A16<=12,Premissas!$B$31,Premissas!$B$32)))) | C16: =Premissas!B22*B16 | D16: =-C16*Premissas!$B$7 | E16: =-C16*Premissas!$B$8 | F16: =-C16*Premissas!$B$9 | G16: =-C16*Premissas!$B$10 | H16: =-Premissas!$B$11 | I16: =-Premissas!B25 | J16: =SUM(C16:I16) | K16: =J16-C16*Premissas!$B$12 | L16: =L15+K16
A17: 13 | B17: =IF(A17<=3,Premissas!$B$28,IF(A17<=6,Premissas!$B$29,IF(A17<=9,Premissas!$B$30,IF(A17<=12,Premissas!$B$31,Premissas!$B$32)))) | C17: =Premissas!B22*B17 | D17: =-C17*Premissas!$B$7 | E17: =-C17*Premissas!$B$8 | F17: =-C17*Premissas!$B$9 | G17: =-C17*Premissas!$B$10 | H17: =-Premissas!$B$11 | I17: =-Premissas!B25 | J17: =SUM(C17:I17) | K17: =J17-C17*Premissas!$B$12 | L17: =L16+K17
A18: 14 | B18: =IF(A18<=3,Premissas!$B$28,IF(A18<=6,Premissas!$B$29,IF(A18<=9,Premissas!$B$30,IF(A18<=12,Premissas!$B$31,Premissas!$B$32)))) | C18: =Premissas!B22*B18 | D18: =-C18*Premissas!$B$7 | E18: =-C18*Premissas!$B$8 | F18: =-C18*Premissas!$B$9 | G18: =-C18*Premissas!$B$10 | H18: =-Premissas!$B$11 | I18: =-Premissas!B25 | J18: =SUM(C18:I18) | K18: =J18-C18*Premissas!$B$12 | L18: =L17+K18
A19: 15 | B19: =IF(A19<=3,Premissas!$B$28,IF(A19<=6,Premissas!$B$29,IF(A19<=9,Premissas!$B$30,IF(A19<=12,Premissas!$B$31,Premissas!$B$32)))) | C19: =Premissas!B22*B19 | D19: =-C19*Premissas!$B$7 | E19: =-C19*Premissas!$B$8 | F19: =-C19*Premissas!$B$9 | G19: =-C19*Premissas!$B$10 | H19: =-Premissas!$B$11 | I19: =-Premissas!B25 | J19: =SUM(C19:I19) | K19: =J19-C19*Premissas!$B$12 | L19: =L18+K19
A20: 16 | B20: =IF(A20<=3,Premissas!$B$28,IF(A20<=6,Premissas!$B$29,IF(A20<=9,Premissas!$B$30,IF(A20<=12,Premissas!$B$31,Premissas!$B$32)))) | C20: =Premissas!B22*B20 | D20: =-C20*Premissas!$B$7 | E20: =-C20*Premissas!$B$8 | F20: =-C20*Premissas!$B$9 | G20: =-C20*Premissas!$B$10 | H20: =-Premissas!$B$11 | I20: =-Premissas!B25 | J20: =SUM(C20:I20) | K20: =J20-C20*Premissas!$B$12 | L20: =L19+K20
A21: 17 | B21: =IF(A21<=3,Premissas!$B$28,IF(A21<=6,Premissas!$B$29,IF(A21<=9,Premissas!$B$30,IF(A21<=12,Premissas!$B$31,Premissas!$B$32)))) | C21: =Premissas!B22*B21 | D21: =-C21*Premissas!$B$7 | E21: =-C21*Premissas!$B$8 | F21: =-C21*Premissas!$B$9 | G21: =-C21*Premissas!$B$10 | H21: =-Premissas!$B$11 | I21: =-Premissas!B25 | J21: =SUM(C21:I21) | K21: =J21-C21*Premissas!$B$12 | L21: =L20+K21
A22: 18 | B22: =IF(A22<=3,Premissas!$B$28,IF(A22<=6,Premissas!$B$29,IF(A22<=9,Premissas!$B$30,IF(A22<=12,Premissas!$B$31,Premissas!$B$32)))) | C22: =Premissas!B22*B22 | D22: =-C22*Premissas!$B$7 | E22: =-C22*Premissas!$B$8 | F22: =-C22*Premissas!$B$9 | G22: =-C22*Premissas!$B$10 | H22: =-Premissas!$B$11 | I22: =-Premissas!B25 | J22: =SUM(C22:I22) | K22: =J22-C22*Premissas!$B$12 | L22: =L21+K22
A23: 19 | B23: =IF(A23<=3,Premissas!$B$28,IF(A23<=6,Premissas!$B$29,IF(A23<=9,Premissas!$B$30,IF(A23<=12,Premissas!$B$31,Premissas!$B$32)))) | C23: =Premissas!B22*B23 | D23: =-C23*Premissas!$B$7 | E23: =-C23*Premissas!$B$8 | F23: =-C23*Premissas!$B$9 | G23: =-C23*Premissas!$B$10 | H23: =-Premissas!$B$11 | I23: =-Premissas!B25 | J23: =SUM(C23:I23) | K23: =J23-C23*Premissas!$B$12 | L23: =L22+K23
A24: 20 | B24: =IF(A24<=3,Premissas!$B$28,IF(A24<=6,Premissas!$B$29,IF(A24<=9,Premissas!$B$30,IF(A24<=12,Premissas!$B$31,Premissas!$B$32)))) | C24: =Premissas!B22*B24 | D24: =-C24*Premissas!$B$7 | E24: =-C24*Premissas!$B$8 | F24: =-C24*Premissas!$B$9 | G24: =-C24*Premissas!$B$10 | H24: =-Premissas!$B$11 | I24: =-Premissas!B25 | J24: =SUM(C24:I24) | K24: =J24-C24*Premissas!$B$12 | L24: =L23+K24
A25: 21 | B25: =IF(A25<=3,Premissas!$B$28,IF(A25<=6,Premissas!$B$29,IF(A25<=9,Premissas!$B$30,IF(A25<=12,Premissas!$B$31,Premissas!$B$32)))) | C25: =Premissas!B22*B25 | D25: =-C25*Premissas!$B$7 | E25: =-C25*Premissas!$B$8 | F25: =-C25*Premissas!$B$9 | G25: =-C25*Premissas!$B$10 | H25: =-Premissas!$B$11 | I25: =-Premissas!B25 | J25: =SUM(C25:I25) | K25: =J25-C25*Premissas!$B$12 | L25: =L24+K25
A26: 22 | B26: =IF(A26<=3,Premissas!$B$28,IF(A26<=6,Premissas!$B$29,IF(A26<=9,Premissas!$B$30,IF(A26<=12,Premissas!$B$31,Premissas!$B$32)))) | C26: =Premissas!B22*B26 | D26: =-C26*Premissas!$B$7 | E26: =-C26*Premissas!$B$8 | F26: =-C26*Premissas!$B$9 | G26: =-C26*Premissas!$B$10 | H26: =-Premissas!$B$11 | I26: =-Premissas!B25 | J26: =SUM(C26:I26) | K26: =J26-C26*Premissas!$B$12 | L26: =L25+K26
A27: 23 | B27: =IF(A27<=3,Premissas!$B$28,IF(A27<=6,Premissas!$B$29,IF(A27<=9,Premissas!$B$30,IF(A27<=12,Premissas!$B$31,Premissas!$B$32)))) | C27: =Premissas!B22*B27 | D27: =-C27*Premissas!$B$7 | E27: =-C27*Premissas!$B$8 | F27: =-C27*Premissas!$B$9 | G27: =-C27*Premissas!$B$10 | H27: =-Premissas!$B$11 | I27: =-Premissas!B25 | J27: =SUM(C27:I27) | K27: =J27-C27*Premissas!$B$12 | L27: =L26+K27
A28: 24 | B28: =IF(A28<=3,Premissas!$B$28,IF(A28<=6,Premissas!$B$29,IF(A28<=9,Premissas!$B$30,IF(A28<=12,Premissas!$B$31,Premissas!$B$32)))) | C28: =Premissas!B22*B28 | D28: =-C28*Premissas!$B$7 | E28: =-C28*Premissas!$B$8 | F28: =-C28*Premissas!$B$9 | G28: =-C28*Premissas!$B$10 | H28: =-Premissas!$B$11 | I28: =-Premissas!B25 | J28: =SUM(C28:I28) | K28: =J28-C28*Premissas!$B$12 | L28: =L27+K28
A29: 25 | B29: =IF(A29<=3,Premissas!$B$28,IF(A29<=6,Premissas!$B$29,IF(A29<=9,Premissas!$B$30,IF(A29<=12,Premissas!$B$31,Premissas!$B$32)))) | C29: =Premissas!B22*B29 | D29: =-C29*Premissas!$B$7 | E29: =-C29*Premissas!$B$8 | F29: =-C29*Premissas!$B$9 | G29: =-C29*Premissas!$B$10 | H29: =-Premissas!$B$11 | I29: =-Premissas!B25 | J29: =SUM(C29:I29) | K29: =J29-C29*Premissas!$B$12 | L29: =L28+K29
A30: 26 | B30: =IF(A30<=3,Premissas!$B$28,IF(A30<=6,Premissas!$B$29,IF(A30<=9,Premissas!$B$30,IF(A30<=12,Premissas!$B$31,Premissas!$B$32)))) | C30: =Premissas!B22*B30 | D30: =-C30*Premissas!$B$7 | E30: =-C30*Premissas!$B$8 | F30: =-C30*Premissas!$B$9 | G30: =-C30*Premissas!$B$10 | H30: =-Premissas!$B$11 | I30: =-Premissas!B25 | J30: =SUM(C30:I30) | K30: =J30-C30*Premissas!$B$12 | L30: =L29+K30
A31: 27 | B31: =IF(A31<=3,Premissas!$B$28,IF(A31<=6,Premissas!$B$29,IF(A31<=9,Premissas!$B$30,IF(A31<=12,Premissas!$B$31,Premissas!$B$32)))) | C31: =Premissas!B22*B31 | D31: =-C31*Premissas!$B$7 | E31: =-C31*Premissas!$B$8 | F31: =-C31*Premissas!$B$9 | G31: =-C31*Premissas!$B$10 | H31: =-Premissas!$B$11 | I31: =-Premissas!B25 | J31: =SUM(C31:I31) | K31: =J31-C31*Premissas!$B$12 | L31: =L30+K31
A32: 28 | B32: =IF(A32<=3,Premissas!$B$28,IF(A32<=6,Premissas!$B$29,IF(A32<=9,Premissas!$B$30,IF(A32<=12,Premissas!$B$31,Premissas!$B$32)))) | C32: =Premissas!B22*B32 | D32: =-C32*Premissas!$B$7 | E32: =-C32*Premissas!$B$8 | F32: =-C32*Premissas!$B$9 | G32: =-C32*Premissas!$B$10 | H32: =-Premissas!$B$11 | I32: =-Premissas!B25 | J32: =SUM(C32:I32) | K32: =J32-C32*Premissas!$B$12 | L32: =L31+K32
A33: 29 | B33: =IF(A33<=3,Premissas!$B$28,IF(A33<=6,Premissas!$B$29,IF(A33<=9,Premissas!$B$30,IF(A33<=12,Premissas!$B$31,Premissas!$B$32)))) | C33: =Premissas!B22*B33 | D33: =-C33*Premissas!$B$7 | E33: =-C33*Premissas!$B$8 | F33: =-C33*Premissas!$B$9 | G33: =-C33*Premissas!$B$10 | H33: =-Premissas!$B$11 | I33: =-Premissas!B25 | J33: =SUM(C33:I33) | K33: =J33-C33*Premissas!$B$12 | L33: =L32+K33
A34: 30 | B34: =IF(A34<=3,Premissas!$B$28,IF(A34<=6,Premissas!$B$29,IF(A34<=9,Premissas!$B$30,IF(A34<=12,Premissas!$B$31,Premissas!$B$32)))) | C34: =Premissas!B22*B34 | D34: =-C34*Premissas!$B$7 | E34: =-C34*Premissas!$B$8 | F34: =-C34*Premissas!$B$9 | G34: =-C34*Premissas!$B$10 | H34: =-Premissas!$B$11 | I34: =-Premissas!B25 | J34: =SUM(C34:I34) | K34: =J34-C34*Premissas!$B$12 | L34: =L33+K34
A35: 31 | B35: =IF(A35<=3,Premissas!$B$28,IF(A35<=6,Premissas!$B$29,IF(A35<=9,Premissas!$B$30,IF(A35<=12,Premissas!$B$31,Premissas!$B$32)))) | C35: =Premissas!B22*B35 | D35: =-C35*Premissas!$B$7 | E35: =-C35*Premissas!$B$8 | F35: =-C35*Premissas!$B$9 | G35: =-C35*Premissas!$B$10 | H35: =-Premissas!$B$11 | I35: =-Premissas!B25 | J35: =SUM(C35:I35) | K35: =J35-C35*Premissas!$B$12 | L35: =L34+K35
A36: 32 | B36: =IF(A36<=3,Premissas!$B$28,IF(A36<=6,Premissas!$B$29,IF(A36<=9,Premissas!$B$30,IF(A36<=12,Premissas!$B$31,Premissas!$B$32)))) | C36: =Premissas!B22*B36 | D36: =-C36*Premissas!$B$7 | E36: =-C36*Premissas!$B$8 | F36: =-C36*Premissas!$B$9 | G36: =-C36*Premissas!$B$10 | H36: =-Premissas!$B$11 | I36: =-Premissas!B25 | J36: =SUM(C36:I36) | K36: =J36-C36*Premissas!$B$12 | L36: =L35+K36
A37: 33 | B37: =IF(A37<=3,Premissas!$B$28,IF(A37<=6,Premissas!$B$29,IF(A37<=9,Premissas!$B$30,IF(A37<=12,Premissas!$B$31,Premissas!$B$32)))) | C37: =Premissas!B22*B37 | D37: =-C37*Premissas!$B$7 | E37: =-C37*Premissas!$B$8 | F37: =-C37*Premissas!$B$9 | G37: =-C37*Premissas!$B$10 | H37: =-Premissas!$B$11 | I37: =-Premissas!B25 | J37: =SUM(C37:I37) | K37: =J37-C37*Premissas!$B$12 | L37: =L36+K37
A38: 34 | B38: =IF(A38<=3,Premissas!$B$28,IF(A38<=6,Premissas!$B$29,IF(A38<=9,Premissas!$B$30,IF(A38<=12,Premissas!$B$31,Premissas!$B$32)))) | C38: =Premissas!B22*B38 | D38: =-C38*Premissas!$B$7 | E38: =-C38*Premissas!$B$8 | F38: =-C38*Premissas!$B$9 | G38: =-C38*Premissas!$B$10 | H38: =-Premissas!$B$11 | I38: =-Premissas!B25 | J38: =SUM(C38:I38) | K38: =J38-C38*Premissas!$B$12 | L38: =L37+K38
A39: 35 | B39: =IF(A39<=3,Premissas!$B$28,IF(A39<=6,Premissas!$B$29,IF(A39<=9,Premissas!$B$30,IF(A39<=12,Premissas!$B$31,Premissas!$B$32)))) | C39: =Premissas!B22*B39 | D39: =-C39*Premissas!$B$7 | E39: =-C39*Premissas!$B$8 | F39: =-C39*Premissas!$B$9 | G39: =-C39*Premissas!$B$10 | H39: =-Premissas!$B$11 | I39: =-Premissas!B25 | J39: =SUM(C39:I39) | K39: =J39-C39*Premissas!$B$12 | L39: =L38+K39
A40: 36 | B40: =IF(A40<=3,Premissas!$B$28,IF(A40<=6,Premissas!$B$29,IF(A40<=9,Premissas!$B$30,IF(A40<=12,Premissas!$B$31,Premissas!$B$32)))) | C40: =Premissas!B22*B40 | D40: =-C40*Premissas!$B$7 | E40: =-C40*Premissas!$B$8 | F40: =-C40*Premissas!$B$9 | G40: =-C40*Premissas!$B$10 | H40: =-Premissas!$B$11 | I40: =-Premissas!B25 | J40: =SUM(C40:I40) | K40: =J40-C40*Premissas!$B$12 | L40: =L39+K40
A41: 37 | B41: =IF(A41<=3,Premissas!$B$28,IF(A41<=6,Premissas!$B$29,IF(A41<=9,Premissas!$B$30,IF(A41<=12,Premissas!$B$31,Premissas!$B$32)))) | C41: =Premissas!B22*B41 | D41: =-C41*Premissas!$B$7 | E41: =-C41*Premissas!$B$8 | F41: =-C41*Premissas!$B$9 | G41: =-C41*Premissas!$B$10 | H41: =-Premissas!$B$11 | I41: =-Premissas!B25 | J41: =SUM(C41:I41) | K41: =J41-C41*Premissas!$B$12 | L41: =L40+K41
...

Sheet Express
A1: UNIDADE EXPRESS — FLUXO MENSAL (60 MESES)
A3: Mês | B3: % rampa | C3: Receita | D3: Impostos | E3: Variáveis | F3: Royalty | G3: Fundo | H3: Tecnologia | I3: Fixos | J3: EBITDA | K3: Fluxo livre | L3: Acumulado
A4: 0 | K4: =-Premissas!C24 | L4: =-Premissas!C24
A5: 1 | B5: =IF(A5<=3,Premissas!$B$28,IF(A5<=6,Premissas!$B$29,IF(A5<=9,Premissas!$B$30,IF(A5<=12,Premissas!$B$31,Premissas!$B$32)))) | C5: =Premissas!C22*B5 | D5: =-C5*Premissas!$B$7 | E5: =-C5*Premissas!$B$8 | F5: =-C5*Premissas!$B$9 | G5: =-C5*Premissas!$B$10 | H5: =-Premissas!$B$11 | I5: =-Premissas!C25 | J5: =SUM(C5:I5) | K5: =J5-C5*Premissas!$B$12 | L5: =L4+K5
A6: 2 | B6: =IF(A6<=3,Premissas!$B$28,IF(A6<=6,Premissas!$B$29,IF(A6<=9,Premissas!$B$30,IF(A6<=12,Premissas!$B$31,Premissas!$B$32)))) | C6: =Premissas!C22*B6 | D6: =-C6*Premissas!$B$7 | E6: =-C6*Premissas!$B$8 | F6: =-C6*Premissas!$B$9 | G6: =-C6*Premissas!$B$10 | H6: =-Premissas!$B$11 | I6: =-Premissas!C25 | J6: =SUM(C6:I6) | K6: =J6-C6*Premissas!$B$12 | L6: =L5+K6
A7: 3 | B7: =IF(A7<=3,Premissas!$B$28,IF(A7<=6,Premissas!$B$29,IF(A7<=9,Premissas!$B$30,IF(A7<=12,Premissas!$B$31,Premissas!$B$32)))) | C7: =Premissas!C22*B7 | D7: =-C7*Premissas!$B$7 | E7: =-C7*Premissas!$B$8 | F7: =-C7*Premissas!$B$9 | G7: =-C7*Premissas!$B$10 | H7: =-Premissas!$B$11 | I7: =-Premissas!C25 | J7: =SUM(C7:I7) | K7: =J7-C7*Premissas!$B$12 | L7: =L6+K7
A8: 4 | B8: =IF(A8<=3,Premissas!$B$28,IF(A8<=6,Premissas!$B$29,IF(A8<=9,Premissas!$B$30,IF(A8<=12,Premissas!$B$31,Premissas!$B$32)))) | C8: =Premissas!C22*B8 | D8: =-C8*Premissas!$B$7 | E8: =-C8*Premissas!$B$8 | F8: =-C8*Premissas!$B$9 | G8: =-C8*Premissas!$B$10 | H8: =-Premissas!$B$11 | I8: =-Premissas!C25 | J8: =SUM(C8:I8) | K8: =J8-C8*Premissas!$B$12 | L8: =L7+K8
A9: 5 | B9: =IF(A9<=3,Premissas!$B$28,IF(A9<=6,Premissas!$B$29,IF(A9<=9,Premissas!$B$30,IF(A9<=12,Premissas!$B$31,Premissas!$B$32)))) | C9: =Premissas!C22*B9 | D9: =-C9*Premissas!$B$7 | E9: =-C9*Premissas!$B$8 | F9: =-C9*Premissas!$B$9 | G9: =-C9*Premissas!$B$10 | H9: =-Premissas!$B$11 | I9: =-Premissas!C25 | J9: =SUM(C9:I9) | K9: =J9-C9*Premissas!$B$12 | L9: =L8+K9
A10: 6 | B10: =IF(A10<=3,Premissas!$B$28,IF(A10<=6,Premissas!$B$29,IF(A10<=9,Premissas!$B$30,IF(A10<=12,Premissas!$B$31,Premissas!$B$32)))) | C10: =Premissas!C22*B10 | D10: =-C10*Premissas!$B$7 | E10: =-C10*Premissas!$B$8 | F10: =-C10*Premissas!$B$9 | G10: =-C10*Premissas!$B$10 | H10: =-Premissas!$B$11 | I10: =-Premissas!C25 | J10: =SUM(C10:I10) | K10: =J10-C10*Premissas!$B$12 | L10: =L9+K10
A11: 7 | B11: =IF(A11<=3,Premissas!$B$28,IF(A11<=6,Premissas!$B$29,IF(A11<=9,Premissas!$B$30,IF(A11<=12,Premissas!$B$31,Premissas!$B$32)))) | C11: =Premissas!C22*B11 | D11: =-C11*Premissas!$B$7 | E11: =-C11*Premissas!$B$8 | F11: =-C11*Premissas!$B$9 | G11: =-C11*Premissas!$B$10 | H11: =-Premissas!$B$11 | I11: =-Premissas!C25 | J11: =SUM(C11:I11) | K11: =J11-C11*Premissas!$B$12 | L11: =L10+K11
A12: 8 | B12: =IF(A12<=3,Premissas!$B$28,IF(A12<=6,Premissas!$B$29,IF(A12<=9,Premissas!$B$30,IF(A12<=12,Premissas!$B$31,Premissas!$B$32)))) | C12: =Premissas!C22*B12 | D12: =-C12*Premissas!$B$7 | E12: =-C12*Premissas!$B$8 | F12: =-C12*Premissas!$B$9 | G12: =-C12*Premissas!$B$10 | H12: =-Premissas!$B$11 | I12: =-Premissas!C25 | J12: =SUM(C12:I12) | K12: =J12-C12*Premissas!$B$12 | L12: =L11+K12
A13: 9 | B13: =IF(A13<=3,Premissas!$B$28,IF(A13<=6,Premissas!$B$29,IF(A13<=9,Premissas!$B$30,IF(A13<=12,Premissas!$B$31,Premissas!$B$32)))) | C13: =Premissas!C22*B13 | D13: =-C13*Premissas!$B$7 | E13: =-C13*Premissas!$B$8 | F13: =-C13*Premissas!$B$9 | G13: =-C13*Premissas!$B$10 | H13: =-Premissas!$B$11 | I13: =-Premissas!C25 | J13: =SUM(C13:I13) | K13: =J13-C13*Premissas!$B$12 | L13: =L12+K13
A14: 10 | B14: =IF(A14<=3,Premissas!$B$28,IF(A14<=6,Premissas!$B$29,IF(A14<=9,Premissas!$B$30,IF(A14<=12,Premissas!$B$31,Premissas!$B$32)))) | C14: =Premissas!C22*B14 | D14: =-C14*Premissas!$B$7 | E14: =-C14*Premissas!$B$8 | F14: =-C14*Premissas!$B$9 | G14: =-C14*Premissas!$B$10 | H14: =-Premissas!$B$11 | I14: =-Premissas!C25 | J14: =SUM(C14:I14) | K14: =J14-C14*Premissas!$B$12 | L14: =L13+K14
A15: 11 | B15: =IF(A15<=3,Premissas!$B$28,IF(A15<=6,Premissas!$B$29,IF(A15<=9,Premissas!$B$30,IF(A15<=12,Premissas!$B$31,Premissas!$B$32)))) | C15: =Premissas!C22*B15 | D15: =-C15*Premissas!$B$7 | E15: =-C15*Premissas!$B$8 | F15: =-C15*Premissas!$B$9 | G15: =-C15*Premissas!$B$10 | H15: =-Premissas!$B$11 | I15: =-Premissas!C25 | J15: =SUM(C15:I15) | K15: =J15-C15*Premissas!$B$12 | L15: =L14+K15
A16: 12 | B16: =IF(A16<=3,Premissas!$B$28,IF(A16<=6,Premissas!$B$29,IF(A16<=9,Premissas!$B$30,IF(A16<=12,Premissas!$B$31,Premissas!$B$32)))) | C16: =Premissas!C22*B16 | D16: =-C16*Premissas!$B$7 | E16: =-C16*Premissas!$B$8 | F16: =-C16*Premissas!$B$9 | G16: =-C16*Premissas!$B$10 | H16: =-Premissas!$B$11 | I16: =-Premissas!C25 | J16: =SUM(C16:I16) | K16: =J16-C16*Premissas!$B$12 | L16: =L15+K16
A17: 13 | B17: =IF(A17<=3,Premissas!$B$28,IF(A17<=6,Premissas!$B$29,IF(A17<=9,Premissas!$B$30,IF(A17<=12,Premissas!$B$31,Premissas!$B$32)))) | C17: =Premissas!C22*B17 | D17: =-C17*Premissas!$B$7 | E17: =-C17*Premissas!$B$8 | F17: =-C17*Premissas!$B$9 | G17: =-C17*Premissas!$B$10 | H17: =-Premissas!$B$11 | I17: =-Premissas!C25 | J17: =SUM(C17:I17) | K17: =J17-C17*Premissas!$B$12 | L17: =L16+K17
A18: 14 | B18: =IF(A18<=3,Premissas!$B$28,IF(A18<=6,Premissas!$B$29,IF(A18<=9,Premissas!$B$30,IF(A18<=12,Premissas!$B$31,Premissas!$B$32)))) | C18: =Premissas!C22*B18 | D18: =-C18*Premissas!$B$7 | E18: =-C18*Premissas!$B$8 | F18: =-C18*Premissas!$B$9 | G18: =-C18*Premissas!$B$10 | H18: =-Premissas!$B$11 | I18: =-Premissas!C25 | J18: =SUM(C18:I18) | K18: =J18-C18*Premissas!$B$12 | L18: =L17+K18
A19: 15 | B19: =IF(A19<=3,Premissas!$B$28,IF(A19<=6,Premissas!$B$29,IF(A19<=9,Premissas!$B$30,IF(A19<=12,Premissas!$B$31,Premissas!$B$32)))) | C19: =Premissas!C22*B19 | D19: =-C19*Premissas!$B$7 | E19: =-C19*Premissas!$B$8 | F19: =-C19*Premissas!$B$9 | G19: =-C19*Premissas!$B$10 | H19: =-Premissas!$B$11 | I19: =-Premissas!C25 | J19: =SUM(C19:I19) | K19: =J19-C19*Premissas!$B$12 | L19: =L18+K19
A20: 16 | B20: =IF(A20<=3,Premissas!$B$28,IF(A20<=6,Premissas!$B$29,IF(A20<=9,Premissas!$B$30,IF(A20<=12,Premissas!$B$31,Premissas!$B$32)))) | C20: =Premissas!C22*B20 | D20: =-C20*Premissas!$B$7 | E20: =-C20*Premissas!$B$8 | F20: =-C20*Premissas!$B$9 | G20: =-C20*Premissas!$B$10 | H20: =-Premissas!$B$11 | I20: =-Premissas!C25 | J20: =SUM(C20:I20) | K20: =J20-C20*Premissas!$B$12 | L20: =L19+K20
A21: 17 | B21: =IF(A21<=3,Premissas!$B$28,IF(A21<=6,Premissas!$B$29,IF(A21<=9,Premissas!$B$30,IF(A21<=12,Premissas!$B$31,Premissas!$B$32)))) | C21: =Premissas!C22*B21 | D21: =-C21*Premissas!$B$7 | E21: =-C21*Premissas!$B$8 | F21: =-C21*Premissas!$B$9 | G21: =-C21*Premissas!$B$10 | H21: =-Premissas!$B$11 | I21: =-Premissas!C25 | J21: =SUM(C21:I21) | K21: =J21-C21*Premissas!$B$12 | L21: =L20+K21
A22: 18 | B22: =IF(A22<=3,Premissas!$B$28,IF(A22<=6,Premissas!$B$29,IF(A22<=9,Premissas!$B$30,IF(A22<=12,Premissas!$B$31,Premissas!$B$32)))) | C22: =Premissas!C22*B22 | D22: =-C22*Premissas!$B$7 | E22: =-C22*Premissas!$B$8 | F22: =-C22*Premissas!$B$9 | G22: =-C22*Premissas!$B$10 | H22: =-Premissas!$B$11 | I22: =-Premissas!C25 | J22: =SUM(C22:I22) | K22: =J22-C22*Premissas!$B$12 | L22: =L21+K22
A23: 19 | B23: =IF(A23<=3,Premissas!$B$28,IF(A23<=6,Premissas!$B$29,IF(A23<=9,Premissas!$B$30,IF(A23<=12,Premissas!$B$31,Premissas!$B$32)))) | C23: =Premissas!C22*B23 | D23: =-C23*Premissas!$B$7 | E23: =-C23*Premissas!$B$8 | F23: =-C23*Premissas!$B$9 | G23: =-C23*Premissas!$B$10 | H23: =-Premissas!$B$11 | I23: =-Premissas!C25 | J23: =SUM(C23:I23) | K23: =J23-C23*Premissas!$B$12 | L23: =L22+K23
A24: 20 | B24: =IF(A24<=3,Premissas!$B$28,IF(A24<=6,Premissas!$B$29,IF(A24<=9,Premissas!$B$30,IF(A24<=12,Premissas!$B$31,Premissas!$B$32)))) | C24: =Premissas!C22*B24 | D24: =-C24*Premissas!$B$7 | E24: =-C24*Premissas!$B$8 | F24: =-C24*Premissas!$B$9 | G24: =-C24*Premissas!$B$10 | H24: =-Premissas!$B$11 | I24: =-Premissas!C25 | J24: =SUM(C24:I24) | K24: =J24-C24*Premissas!$B$12 | L24: =L23+K24
A25: 21 | B25: =IF(A25<=3,Premissas!$B$28,IF(A25<=6,Premissas!$B$29,IF(A25<=9,Premissas!$B$30,IF(A25<=12,Premissas!$B$31,Premissas!$B$32)))) | C25: =Premissas!C22*B25 | D25: =-C25*Premissas!$B$7 | E25: =-C25*Premissas!$B$8 | F25: =-C25*Premissas!$B$9 | G25: =-C25*Premissas!$B$10 | H25: =-Premissas!$B$11 | I25: =-Premissas!C25 | J25: =SUM(C25:I25) | K25: =J25-C25*Premissas!$B$12 | L25: =L24+K25
A26: 22 | B26: =IF(A26<=3,Premissas!$B$28,IF(A26<=6,Premissas!$B$29,IF(A26<=9,Premissas!$B$30,IF(A26<=12,Premissas!$B$31,Premissas!$B$32)))) | C26: =Premissas!C22*B26 | D26: =-C26*Premissas!$B$7 | E26: =-C26*Premissas!$B$8 | F26: =-C26*Premissas!$B$9 | G26: =-C26*Premissas!$B$10 | H26: =-Premissas!$B$11 | I26: =-Premissas!C25 | J26: =SUM(C26:I26) | K26: =J26-C26*Premissas!$B$12 | L26: =L25+K26
A27: 23 | B27: =IF(A27<=3,Premissas!$B$28,IF(A27<=6,Premissas!$B$29,IF(A27<=9,Premissas!$B$30,IF(A27<=12,Premissas!$B$31,Premissas!$B$32)))) | C27: =Premissas!C22*B27 | D27: =-C27*Premissas!$B$7 | E27: =-C27*Premissas!$B$8 | F27: =-C27*Premissas!$B$9 | G27: =-C27*Premissas!$B$10 | H27: =-Premissas!$B$11 | I27: =-Premissas!C25 | J27: =SUM(C27:I27) | K27: =J27-C27*Premissas!$B$12 | L27: =L26+K27
A28: 24 | B28: =IF(A28<=3,Premissas!$B$28,IF(A28<=6,Premissas!$B$29,IF(A28<=9,Premissas!$B$30,IF(A28<=12,Premissas!$B$31,Premissas!$B$32)))) | C28: =Premissas!C22*B28 | D28: =-C28*Premissas!$B$7 | E28: =-C28*Premissas!$B$8 | F28: =-C28*Premissas!$B$9 | G28: =-C28*Premissas!$B$10 | H28: =-Premissas!$B$11 | I28: =-Premissas!C25 | J28: =SUM(C28:I28) | K28: =J28-C28*Premissas!$B$12 | L28: =L27+K28
A29: 25 | B29: =IF(A29<=3,Premissas!$B$28,IF(A29<=6,Premissas!$B$29,IF(A29<=9,Premissas!$B$30,IF(A29<=12,Premissas!$B$31,Premissas!$B$32)))) | C29: =Premissas!C22*B29 | D29: =-C29*Premissas!$B$7 | E29: =-C29*Premissas!$B$8 | F29: =-C29*Premissas!$B$9 | G29: =-C29*Premissas!$B$10 | H29: =-Premissas!$B$11 | I29: =-Premissas!C25 | J29: =SUM(C29:I29) | K29: =J29-C29*Premissas!$B$12 | L29: =L28+K29
A30: 26 | B30: =IF(A30<=3,Premissas!$B$28,IF(A30<=6,Premissas!$B$29,IF(A30<=9,Premissas!$B$30,IF(A30<=12,Premissas!$B$31,Premissas!$B$32)))) | C30: =Premissas!C22*B30 | D30: =-C30*Premissas!$B$7 | E30: =-C30*Premissas!$B$8 | F30: =-C30*Premissas!$B$9 | G30: =-C30*Premissas!$B$10 | H30: =-Premissas!$B$11 | I30: =-Premissas!C25 | J30: =SUM(C30:I30) | K30: =J30-C30*Premissas!$B$12 | L30: =L29+K30
A31: 27 | B31: =IF(A31<=3,Premissas!$B$28,IF(A31<=6,Premissas!$B$29,IF(A31<=9,Premissas!$B$30,IF(A31<=12,Premissas!$B$31,Premissas!$B$32)))) | C31: =Premissas!C22*B31 | D31: =-C31*Premissas!$B$7 | E31: =-C31*Premissas!$B$8 | F31: =-C31*Premissas!$B$9 | G31: =-C31*Premissas!$B$10 | H31: =-Premissas!$B$11 | I31: =-Premissas!C25 | J31: =SUM(C31:I31) | K31: =J31-C31*Premissas!$B$12 | L31: =L30+K31
A32: 28 | B32: =IF(A32<=3,Premissas!$B$28,IF(A32<=6,Premissas!$B$29,IF(A32<=9,Premissas!$B$30,IF(A32<=12,Premissas!$B$31,Premissas!$B$32)))) | C32: =Premissas!C22*B32 | D32: =-C32*Premissas!$B$7 | E32: =-C32*Premissas!$B$8 | F32: =-C32*Premissas!$B$9 | G32: =-C32*Premissas!$B$10 | H32: =-Premissas!$B$11 | I32: =-Premissas!C25 | J32: =SUM(C32:I32) | K32: =J32-C32*Premissas!$B$12 | L32: =L31+K32
A33: 29 | B33: =IF(A33<=3,Premissas!$B$28,IF(A33<=6,Premissas!$B$29,IF(A33<=9,Premissas!$B$30,IF(A33<=12,Premissas!$B$31,Premissas!$B$32)))) | C33: =Premissas!C22*B33 | D33: =-C33*Premissas!$B$7 | E33: =-C33*Premissas!$B$8 | F33: =-C33*Premissas!$B$9 | G33: =-C33*Premissas!$B$10 | H33: =-Premissas!$B$11 | I33: =-Premissas!C25 | J33: =SUM(C33:I33) | K33: =J33-C33*Premissas!$B$12 | L33: =L32+K33
A34: 30 | B34: =IF(A34<=3,Premissas!$B$28,IF(A34<=6,Premissas!$B$29,IF(A34<=9,Premissas!$B$30,IF(A34<=12,Premissas!$B$31,Premissas!$B$32)))) | C34: =Premissas!C22*B34 | D34: =-C34*Premissas!$B$7 | E34: =-C34*Premissas!$B$8 | F34: =-C34*Premissas!$B$9 | G34: =-C34*Premissas!$B$10 | H34: =-Premissas!$B$11 | I34: =-Premissas!C25 | J34: =SUM(C34:I34) | K34: =J34-C34*Premissas!$B$12 | L34: =L33+K34
A35: 31 | B35: =IF(A35<=3,Premissas!$B$28,IF(A35<=6,Premissas!$B$29,IF(A35<=9,Premissas!$B$30,IF(A35<=12,Premissas!$B$31,Premissas!$B$32)))) | C35: =Premissas!C22*B35 | D35: =-C35*Premissas!$B$7 | E35: =-C35*Premissas!$B$8 | F35: =-C35*Premissas!$B$9 | G35: =-C35*Premissas!$B$10 | H35: =-Premissas!$B$11 | I35: =-Premissas!C25 | J35: =SUM(C35:I35) | K35: =J35-C35*Premissas!$B$12 | L35: =L34+K35
A36: 32 | B36: =IF(A36<=3,Premissas!$B$28,IF(A36<=6,Premissas!$B$29,IF(A36<=9,Premissas!$B$30,IF(A36<=12,Premissas!$B$31,Premissas!$B$32)))) | C36: =Premissas!C22*B36 | D36: =-C36*Premissas!$B$7 | E36: =-C36*Premissas!$B$8 | F36: =-C36*Premissas!$B$9 | G36: =-C36*Premissas!$B$10 | H36: =-Premissas!$B$11 | I36: =-Premissas!C25 | J36: =SUM(C36:I36) | K36: =J36-C36*Premissas!$B$12 | L36: =L35+K36
A37: 33 | B37: =IF(A37<=3,Premissas!$B$28,IF(A37<=6,Premissas!$B$29,IF(A37<=9,Premissas!$B$30,IF(A37<=12,Premissas!$B$31,Premissas!$B$32)))) | C37: =Premissas!C22*B37 | D37: =-C37*Premissas!$B$7 | E37: =-C37*Premissas!$B$8 | F37: =-C37*Premissas!$B$9 | G37: =-C37*Premissas!$B$10 | H37: =-Premissas!$B$11 | I37: =-Premissas!C25 | J37: =SUM(C37:I37) | K37: =J37-C37*Premissas!$B$12 | L37: =L36+K37
A38: 34 | B38: =IF(A38<=3,Premissas!$B$28,IF(A38<=6,Premissas!$B$29,IF(A38<=9,Premissas!$B$30,IF(A38<=12,Premissas!$B$31,Premissas!$B$32)))) | C38: =Premissas!C22*B38 | D38: =-C38*Premissas!$B$7 | E38: =-C38*Premissas!$B$8 | F38: =-C38*Premissas!$B$9 | G38: =-C38*Premissas!$B$10 | H38: =-Premissas!$B$11 | I38: =-Premissas!C25 | J38: =SUM(C38:I38) | K38: =J38-C38*Premissas!$B$12 | L38: =L37+K38
A39: 35 | B39: =IF(A39<=3,Premissas!$B$28,IF(A39<=6,Premissas!$B$29,IF(A39<=9,Premissas!$B$30,IF(A39<=12,Premissas!$B$31,Premissas!$B$32)))) | C39: =Premissas!C22*B39 | D39: =-C39*Premissas!$B$7 | E39: =-C39*Premissas!$B$8 | F39: =-C39*Premissas!$B$9 | G39: =-C39*Premissas!$B$10 | H39: =-Premissas!$B$11 | I39: =-Premissas!C25 | J39: =SUM(C39:I39) | K39: =J39-C39*Premissas!$B$12 | L39: =L38+K39
A40: 36 | B40: =IF(A40<=3,Premissas!$B$28,IF(A40<=6,Premissas!$B$29,IF(A40<=9,Premissas!$B$30,IF(A40<=12,Premissas!$B$31,Premissas!$B$32)))) | C40: =Premissas!C22*B40 | D40: =-C40*Premissas!$B$7 | E40: =-C40*Premissas!$B$8 | F40: =-C40*Premissas!$B$9 | G40: =-C40*Premissas!$B$10 | H40: =-Premissas!$B$11 | I40: =-Premissas!C25 | J40: =SUM(C40:I40) | K40: =J40-C40*Premissas!$B$12 | L40: =L39+K40
A41: 37 | B41: =IF(A41<=3,Premissas!$B$28,IF(A41<=6,Premissas!$B$29,IF(A41<=9,Premissas!$B$30,IF(A41<=12,Premissas!$B$31,Premissas!$B$32)))) | C41: =Premissas!C22*B41 | D41: =-C41*Premissas!$B$7 | E41: =-C41*Premissas!$B$8 | F41: =-C41*Premissas!$B$9 | G41: =-C41*Premissas!$B$10 | H41: =-Premissas!$B$11 | I41: =-Premissas!C25 | J41: =SUM(C41:I41) | K41: =J41-C41*Premissas!$B$12 | L41: =L40+K41
...

Sheet Prime
A1: UNIDADE PRIME — FLUXO MENSAL (60 MESES)
A3: Mês | B3: % rampa | C3: Receita | D3: Impostos | E3: Variáveis | F3: Royalty | G3: Fundo | H3: Tecnologia | I3: Fixos | J3: EBITDA | K3: Fluxo livre | L3: Acumulado
A4: 0 | K4: =-Premissas!D24 | L4: =-Premissas!D24
A5: 1 | B5: =IF(A5<=3,Premissas!$B$28,IF(A5<=6,Premissas!$B$29,IF(A5<=9,Premissas!$B$30,IF(A5<=12,Premissas!$B$31,Premissas!$B$32)))) | C5: =Premissas!D22*B5 | D5: =-C5*Premissas!$B$7 | E5: =-C5*Premissas!$B$8 | F5: =-C5*Premissas!$B$9 | G5: =-C5*Premissas!$B$10 | H5: =-Premissas!$B$11 | I5: =-Premissas!D25 | J5: =SUM(C5:I5) | K5: =J5-C5*Premissas!$B$12 | L5: =L4+K5
A6: 2 | B6: =IF(A6<=3,Premissas!$B$28,IF(A6<=6,Premissas!$B$29,IF(A6<=9,Premissas!$B$30,IF(A6<=12,Premissas!$B$31,Premissas!$B$32)))) | C6: =Premissas!D22*B6 | D6: =-C6*Premissas!$B$7 | E6: =-C6*Premissas!$B$8 | F6: =-C6*Premissas!$B$9 | G6: =-C6*Premissas!$B$10 | H6: =-Premissas!$B$11 | I6: =-Premissas!D25 | J6: =SUM(C6:I6) | K6: =J6-C6*Premissas!$B$12 | L6: =L5+K6
A7: 3 | B7: =IF(A7<=3,Premissas!$B$28,IF(A7<=6,Premissas!$B$29,IF(A7<=9,Premissas!$B$30,IF(A7<=12,Premissas!$B$31,Premissas!$B$32)))) | C7: =Premissas!D22*B7 | D7: =-C7*Premissas!$B$7 | E7: =-C7*Premissas!$B$8 | F7: =-C7*Premissas!$B$9 | G7: =-C7*Premissas!$B$10 | H7: =-Premissas!$B$11 | I7: =-Premissas!D25 | J7: =SUM(C7:I7) | K7: =J7-C7*Premissas!$B$12 | L7: =L6+K7
A8: 4 | B8: =IF(A8<=3,Premissas!$B$28,IF(A8<=6,Premissas!$B$29,IF(A8<=9,Premissas!$B$30,IF(A8<=12,Premissas!$B$31,Premissas!$B$32)))) | C8: =Premissas!D22*B8 | D8: =-C8*Premissas!$B$7 | E8: =-C8*Premissas!$B$8 | F8: =-C8*Premissas!$B$9 | G8: =-C8*Premissas!$B$10 | H8: =-Premissas!$B$11 | I8: =-Premissas!D25 | J8: =SUM(C8:I8) | K8: =J8-C8*Premissas!$B$12 | L8: =L7+K8
A9: 5 | B9: =IF(A9<=3,Premissas!$B$28,IF(A9<=6,Premissas!$B$29,IF(A9<=9,Premissas!$B$30,IF(A9<=12,Premissas!$B$31,Premissas!$B$32)))) | C9: =Premissas!D22*B9 | D9: =-C9*Premissas!$B$7 | E9: =-C9*Premissas!$B$8 | F9: =-C9*Premissas!$B$9 | G9: =-C9*Premissas!$B$10 | H9: =-Premissas!$B$11 | I9: =-Premissas!D25 | J9: =SUM(C9:I9) | K9: =J9-C9*Premissas!$B$12 | L9: =L8+K9
A10: 6 | B10: =IF(A10<=3,Premissas!$B$28,IF(A10<=6,Premissas!$B$29,IF(A10<=9,Premissas!$B$30,IF(A10<=12,Premissas!$B$31,Premissas!$B$32)))) | C10: =Premissas!D22*B10 | D10: =-C10*Premissas!$B$7 | E10: =-C10*Premissas!$B$8 | F10: =-C10*Premissas!$B$9 | G10: =-C10*Premissas!$B$10 | H10: =-Premissas!$B$11 | I10: =-Premissas!D25 | J10: =SUM(C10:I10) | K10: =J10-C10*Premissas!$B$12 | L10: =L9+K10
A11: 7 | B11: =IF(A11<=3,Premissas!$B$28,IF(A11<=6,Premissas!$B$29,IF(A11<=9,Premissas!$B$30,IF(A11<=12,Premissas!$B$31,Premissas!$B$32)))) | C11: =Premissas!D22*B11 | D11: =-C11*Premissas!$B$7 | E11: =-C11*Premissas!$B$8 | F11: =-C11*Premissas!$B$9 | G11: =-C11*Premissas!$B$10 | H11: =-Premissas!$B$11 | I11: =-Premissas!D25 | J11: =SUM(C11:I11) | K11: =J11-C11*Premissas!$B$12 | L11: =L10+K11
A12: 8 | B12: =IF(A12<=3,Premissas!$B$28,IF(A12<=6,Premissas!$B$29,IF(A12<=9,Premissas!$B$30,IF(A12<=12,Premissas!$B$31,Premissas!$B$32)))) | C12: =Premissas!D22*B12 | D12: =-C12*Premissas!$B$7 | E12: =-C12*Premissas!$B$8 | F12: =-C12*Premissas!$B$9 | G12: =-C12*Premissas!$B$10 | H12: =-Premissas!$B$11 | I12: =-Premissas!D25 | J12: =SUM(C12:I12) | K12: =J12-C12*Premissas!$B$12 | L12: =L11+K12
A13: 9 | B13: =IF(A13<=3,Premissas!$B$28,IF(A13<=6,Premissas!$B$29,IF(A13<=9,Premissas!$B$30,IF(A13<=12,Premissas!$B$31,Premissas!$B$32)))) | C13: =Premissas!D22*B13 | D13: =-C13*Premissas!$B$7 | E13: =-C13*Premissas!$B$8 | F13: =-C13*Premissas!$B$9 | G13: =-C13*Premissas!$B$10 | H13: =-Premissas!$B$11 | I13: =-Premissas!D25 | J13: =SUM(C13:I13) | K13: =J13-C13*Premissas!$B$12 | L13: =L12+K13
A14: 10 | B14: =IF(A14<=3,Premissas!$B$28,IF(A14<=6,Premissas!$B$29,IF(A14<=9,Premissas!$B$30,IF(A14<=12,Premissas!$B$31,Premissas!$B$32)))) | C14: =Premissas!D22*B14 | D14: =-C14*Premissas!$B$7 | E14: =-C14*Premissas!$B$8 | F14: =-C14*Premissas!$B$9 | G14: =-C14*Premissas!$B$10 | H14: =-Premissas!$B$11 | I14: =-Premissas!D25 | J14: =SUM(C14:I14) | K14: =J14-C14*Premissas!$B$12 | L14: =L13+K14
A15: 11 | B15: =IF(A15<=3,Premissas!$B$28,IF(A15<=6,Premissas!$B$29,IF(A15<=9,Premissas!$B$30,IF(A15<=12,Premissas!$B$31,Premissas!$B$32)))) | C15: =Premissas!D22*B15 | D15: =-C15*Premissas!$B$7 | E15: =-C15*Premissas!$B$8 | F15: =-C15*Premissas!$B$9 | G15: =-C15*Premissas!$B$10 | H15: =-Premissas!$B$11 | I15: =-Premissas!D25 | J15: =SUM(C15:I15) | K15: =J15-C15*Premissas!$B$12 | L15: =L14+K15
A16: 12 | B16: =IF(A16<=3,Premissas!$B$28,IF(A16<=6,Premissas!$B$29,IF(A16<=9,Premissas!$B$30,IF(A16<=12,Premissas!$B$31,Premissas!$B$32)))) | C16: =Premissas!D22*B16 | D16: =-C16*Premissas!$B$7 | E16: =-C16*Premissas!$B$8 | F16: =-C16*Premissas!$B$9 | G16: =-C16*Premissas!$B$10 | H16: =-Premissas!$B$11 | I16: =-Premissas!D25 | J16: =SUM(C16:I16) | K16: =J16-C16*Premissas!$B$12 | L16: =L15+K16
A17: 13 | B17: =IF(A17<=3,Premissas!$B$28,IF(A17<=6,Premissas!$B$29,IF(A17<=9,Premissas!$B$30,IF(A17<=12,Premissas!$B$31,Premissas!$B$32)))) | C17: =Premissas!D22*B17 | D17: =-C17*Premissas!$B$7 | E17: =-C17*Premissas!$B$8 | F17: =-C17*Premissas!$B$9 | G17: =-C17*Premissas!$B$10 | H17: =-Premissas!$B$11 | I17: =-Premissas!D25 | J17: =SUM(C17:I17) | K17: =J17-C17*Premissas!$B$12 | L17: =L16+K17
A18: 14 | B18: =IF(A18<=3,Premissas!$B$28,IF(A18<=6,Premissas!$B$29,IF(A18<=9,Premissas!$B$30,IF(A18<=12,Premissas!$B$31,Premissas!$B$32)))) | C18: =Premissas!D22*B18 | D18: =-C18*Premissas!$B$7 | E18: =-C18*Premissas!$B$8 | F18: =-C18*Premissas!$B$9 | G18: =-C18*Premissas!$B$10 | H18: =-Premissas!$B$11 | I18: =-Premissas!D25 | J18: =SUM(C18:I18) | K18: =J18-C18*Premissas!$B$12 | L18: =L17+K18
A19: 15 | B19: =IF(A19<=3,Premissas!$B$28,IF(A19<=6,Premissas!$B$29,IF(A19<=9,Premissas!$B$30,IF(A19<=12,Premissas!$B$31,Premissas!$B$32)))) | C19: =Premissas!D22*B19 | D19: =-C19*Premissas!$B$7 | E19: =-C19*Premissas!$B$8 | F19: =-C19*Premissas!$B$9 | G19: =-C19*Premissas!$B$10 | H19: =-Premissas!$B$11 | I19: =-Premissas!D25 | J19: =SUM(C19:I19) | K19: =J19-C19*Premissas!$B$12 | L19: =L18+K19
A20: 16 | B20: =IF(A20<=3,Premissas!$B$28,IF(A20<=6,Premissas!$B$29,IF(A20<=9,Premissas!$B$30,IF(A20<=12,Premissas!$B$31,Premissas!$B$32)))) | C20: =Premissas!D22*B20 | D20: =-C20*Premissas!$B$7 | E20: =-C20*Premissas!$B$8 | F20: =-C20*Premissas!$B$9 | G20: =-C20*Premissas!$B$10 | H20: =-Premissas!$B$11 | I20: =-Premissas!D25 | J20: =SUM(C20:I20) | K20: =J20-C20*Premissas!$B$12 | L20: =L19+K20
A21: 17 | B21: =IF(A21<=3,Premissas!$B$28,IF(A21<=6,Premissas!$B$29,IF(A21<=9,Premissas!$B$30,IF(A21<=12,Premissas!$B$31,Premissas!$B$32)))) | C21: =Premissas!D22*B21 | D21: =-C21*Premissas!$B$7 | E21: =-C21*Premissas!$B$8 | F21: =-C21*Premissas!$B$9 | G21: =-C21*Premissas!$B$10 | H21: =-Premissas!$B$11 | I21: =-Premissas!D25 | J21: =SUM(C21:I21) | K21: =J21-C21*Premissas!$B$12 | L21: =L20+K21
A22: 18 | B22: =IF(A22<=3,Premissas!$B$28,IF(A22<=6,Premissas!$B$29,IF(A22<=9,Premissas!$B$30,IF(A22<=12,Premissas!$B$31,Premissas!$B$32)))) | C22: =Premissas!D22*B22 | D22: =-C22*Premissas!$B$7 | E22: =-C22*Premissas!$B$8 | F22: =-C22*Premissas!$B$9 | G22: =-C22*Premissas!$B$10 | H22: =-Premissas!$B$11 | I22: =-Premissas!D25 | J22: =SUM(C22:I22) | K22: =J22-C22*Premissas!$B$12 | L22: =L21+K22
A23: 19 | B23: =IF(A23<=3,Premissas!$B$28,IF(A23<=6,Premissas!$B$29,IF(A23<=9,Premissas!$B$30,IF(A23<=12,Premissas!$B$31,Premissas!$B$32)))) | C23: =Premissas!D22*B23 | D23: =-C23*Premissas!$B$7 | E23: =-C23*Premissas!$B$8 | F23: =-C23*Premissas!$B$9 | G23: =-C23*Premissas!$B$10 | H23: =-Premissas!$B$11 | I23: =-Premissas!D25 | J23: =SUM(C23:I23) | K23: =J23-C23*Premissas!$B$12 | L23: =L22+K23
A24: 20 | B24: =IF(A24<=3,Premissas!$B$28,IF(A24<=6,Premissas!$B$29,IF(A24<=9,Premissas!$B$30,IF(A24<=12,Premissas!$B$31,Premissas!$B$32)))) | C24: =Premissas!D22*B24 | D24: =-C24*Premissas!$B$7 | E24: =-C24*Premissas!$B$8 | F24: =-C24*Premissas!$B$9 | G24: =-C24*Premissas!$B$10 | H24: =-Premissas!$B$11 | I24: =-Premissas!D25 | J24: =SUM(C24:I24) | K24: =J24-C24*Premissas!$B$12 | L24: =L23+K24
A25: 21 | B25: =IF(A25<=3,Premissas!$B$28,IF(A25<=6,Premissas!$B$29,IF(A25<=9,Premissas!$B$30,IF(A25<=12,Premissas!$B$31,Premissas!$B$32)))) | C25: =Premissas!D22*B25 | D25: =-C25*Premissas!$B$7 | E25: =-C25*Premissas!$B$8 | F25: =-C25*Premissas!$B$9 | G25: =-C25*Premissas!$B$10 | H25: =-Premissas!$B$11 | I25: =-Premissas!D25 | J25: =SUM(C25:I25) | K25: =J25-C25*Premissas!$B$12 | L25: =L24+K25
A26: 22 | B26: =IF(A26<=3,Premissas!$B$28,IF(A26<=6,Premissas!$B$29,IF(A26<=9,Premissas!$B$30,IF(A26<=12,Premissas!$B$31,Premissas!$B$32)))) | C26: =Premissas!D22*B26 | D26: =-C26*Premissas!$B$7 | E26: =-C26*Premissas!$B$8 | F26: =-C26*Premissas!$B$9 | G26: =-C26*Premissas!$B$10 | H26: =-Premissas!$B$11 | I26: =-Premissas!D25 | J26: =SUM(C26:I26) | K26: =J26-C26*Premissas!$B$12 | L26: =L25+K26
A27: 23 | B27: =IF(A27<=3,Premissas!$B$28,IF(A27<=6,Premissas!$B$29,IF(A27<=9,Premissas!$B$30,IF(A27<=12,Premissas!$B$31,Premissas!$B$32)))) | C27: =Premissas!D22*B27 | D27: =-C27*Premissas!$B$7 | E27: =-C27*Premissas!$B$8 | F27: =-C27*Premissas!$B$9 | G27: =-C27*Premissas!$B$10 | H27: =-Premissas!$B$11 | I27: =-Premissas!D25 | J27: =SUM(C27:I27) | K27: =J27-C27*Premissas!$B$12 | L27: =L26+K27
A28: 24 | B28: =IF(A28<=3,Premissas!$B$28,IF(A28<=6,Premissas!$B$29,IF(A28<=9,Premissas!$B$30,IF(A28<=12,Premissas!$B$31,Premissas!$B$32)))) | C28: =Premissas!D22*B28 | D28: =-C28*Premissas!$B$7 | E28: =-C28*Premissas!$B$8 | F28: =-C28*Premissas!$B$9 | G28: =-C28*Premissas!$B$10 | H28: =-Premissas!$B$11 | I28: =-Premissas!D25 | J28: =SUM(C28:I28) | K28: =J28-C28*Premissas!$B$12 | L28: =L27+K28
A29: 25 | B29: =IF(A29<=3,Premissas!$B$28,IF(A29<=6,Premissas!$B$29,IF(A29<=9,Premissas!$B$30,IF(A29<=12,Premissas!$B$31,Premissas!$B$32)))) | C29: =Premissas!D22*B29 | D29: =-C29*Premissas!$B$7 | E29: =-C29*Premissas!$B$8 | F29: =-C29*Premissas!$B$9 | G29: =-C29*Premissas!$B$10 | H29: =-Premissas!$B$11 | I29: =-Premissas!D25 | J29: =SUM(C29:I29) | K29: =J29-C29*Premissas!$B$12 | L29: =L28+K29
A30: 26 | B30: =IF(A30<=3,Premissas!$B$28,IF(A30<=6,Premissas!$B$29,IF(A30<=9,Premissas!$B$30,IF(A30<=12,Premissas!$B$31,Premissas!$B$32)))) | C30: =Premissas!D22*B30 | D30: =-C30*Premissas!$B$7 | E30: =-C30*Premissas!$B$8 | F30: =-C30*Premissas!$B$9 | G30: =-C30*Premissas!$B$10 | H30: =-Premissas!$B$11 | I30: =-Premissas!D25 | J30: =SUM(C30:I30) | K30: =J30-C30*Premissas!$B$12 | L30: =L29+K30
A31: 27 | B31: =IF(A31<=3,Premissas!$B$28,IF(A31<=6,Premissas!$B$29,IF(A31<=9,Premissas!$B$30,IF(A31<=12,Premissas!$B$31,Premissas!$B$32)))) | C31: =Premissas!D22*B31 | D31: =-C31*Premissas!$B$7 | E31: =-C31*Premissas!$B$8 | F31: =-C31*Premissas!$B$9 | G31: =-C31*Premissas!$B$10 | H31: =-Premissas!$B$11 | I31: =-Premissas!D25 | J31: =SUM(C31:I31) | K31: =J31-C31*Premissas!$B$12 | L31: =L30+K31
A32: 28 | B32: =IF(A32<=3,Premissas!$B$28,IF(A32<=6,Premissas!$B$29,IF(A32<=9,Premissas!$B$30,IF(A32<=12,Premissas!$B$31,Premissas!$B$32)))) | C32: =Premissas!D22*B32 | D32: =-C32*Premissas!$B$7 | E32: =-C32*Premissas!$B$8 | F32: =-C32*Premissas!$B$9 | G32: =-C32*Premissas!$B$10 | H32: =-Premissas!$B$11 | I32: =-Premissas!D25 | J32: =SUM(C32:I32) | K32: =J32-C32*Premissas!$B$12 | L32: =L31+K32
A33: 29 | B33: =IF(A33<=3,Premissas!$B$28,IF(A33<=6,Premissas!$B$29,IF(A33<=9,Premissas!$B$30,IF(A33<=12,Premissas!$B$31,Premissas!$B$32)))) | C33: =Premissas!D22*B33 | D33: =-C33*Premissas!$B$7 | E33: =-C33*Premissas!$B$8 | F33: =-C33*Premissas!$B$9 | G33: =-C33*Premissas!$B$10 | H33: =-Premissas!$B$11 | I33: =-Premissas!D25 | J33: =SUM(C33:I33) | K33: =J33-C33*Premissas!$B$12 | L33: =L32+K33
A34: 30 | B34: =IF(A34<=3,Premissas!$B$28,IF(A34<=6,Premissas!$B$29,IF(A34<=9,Premissas!$B$30,IF(A34<=12,Premissas!$B$31,Premissas!$B$32)))) | C34: =Premissas!D22*B34 | D34: =-C34*Premissas!$B$7 | E34: =-C34*Premissas!$B$8 | F34: =-C34*Premissas!$B$9 | G34: =-C34*Premissas!$B$10 | H34: =-Premissas!$B$11 | I34: =-Premissas!D25 | J34: =SUM(C34:I34) | K34: =J34-C34*Premissas!$B$12 | L34: =L33+K34
A35: 31 | B35: =IF(A35<=3,Premissas!$B$28,IF(A35<=6,Premissas!$B$29,IF(A35<=9,Premissas!$B$30,IF(A35<=12,Premissas!$B$31,Premissas!$B$32)))) | C35: =Premissas!D22*B35 | D35: =-C35*Premissas!$B$7 | E35: =-C35*Premissas!$B$8 | F35: =-C35*Premissas!$B$9 | G35: =-C35*Premissas!$B$10 | H35: =-Premissas!$B$11 | I35: =-Premissas!D25 | J35: =SUM(C35:I35) | K35: =J35-C35*Premissas!$B$12 | L35: =L34+K35
A36: 32 | B36: =IF(A36<=3,Premissas!$B$28,IF(A36<=6,Premissas!$B$29,IF(A36<=9,Premissas!$B$30,IF(A36<=12,Premissas!$B$31,Premissas!$B$32)))) | C36: =Premissas!D22*B36 | D36: =-C36*Premissas!$B$7 | E36: =-C36*Premissas!$B$8 | F36: =-C36*Premissas!$B$9 | G36: =-C36*Premissas!$B$10 | H36: =-Premissas!$B$11 | I36: =-Premissas!D25 | J36: =SUM(C36:I36) | K36: =J36-C36*Premissas!$B$12 | L36: =L35+K36
A37: 33 | B37: =IF(A37<=3,Premissas!$B$28,IF(A37<=6,Premissas!$B$29,IF(A37<=9,Premissas!$B$30,IF(A37<=12,Premissas!$B$31,Premissas!$B$32)))) | C37: =Premissas!D22*B37 | D37: =-C37*Premissas!$B$7 | E37: =-C37*Premissas!$B$8 | F37: =-C37*Premissas!$B$9 | G37: =-C37*Premissas!$B$10 | H37: =-Premissas!$B$11 | I37: =-Premissas!D25 | J37: =SUM(C37:I37) | K37: =J37-C37*Premissas!$B$12 | L37: =L36+K37
A38: 34 | B38: =IF(A38<=3,Premissas!$B$28,IF(A38<=6,Premissas!$B$29,IF(A38<=9,Premissas!$B$30,IF(A38<=12,Premissas!$B$31,Premissas!$B$32)))) | C38: =Premissas!D22*B38 | D38: =-C38*Premissas!$B$7 | E38: =-C38*Premissas!$B$8 | F38: =-C38*Premissas!$B$9 | G38: =-C38*Premissas!$B$10 | H38: =-Premissas!$B$11 | I38: =-Premissas!D25 | J38: =SUM(C38:I38) | K38: =J38-C38*Premissas!$B$12 | L38: =L37+K38
A39: 35 | B39: =IF(A39<=3,Premissas!$B$28,IF(A39<=6,Premissas!$B$29,IF(A39<=9,Premissas!$B$30,IF(A39<=12,Premissas!$B$31,Premissas!$B$32)))) | C39: =Premissas!D22*B39 | D39: =-C39*Premissas!$B$7 | E39: =-C39*Premissas!$B$8 | F39: =-C39*Premissas!$B$9 | G39: =-C39*Premissas!$B$10 | H39: =-Premissas!$B$11 | I39: =-Premissas!D25 | J39: =SUM(C39:I39) | K39: =J39-C39*Premissas!$B$12 | L39: =L38+K39
A40: 36 | B40: =IF(A40<=3,Premissas!$B$28,IF(A40<=6,Premissas!$B$29,IF(A40<=9,Premissas!$B$30,IF(A40<=12,Premissas!$B$31,Premissas!$B$32)))) | C40: =Premissas!D22*B40 | D40: =-C40*Premissas!$B$7 | E40: =-C40*Premissas!$B$8 | F40: =-C40*Premissas!$B$9 | G40: =-C40*Premissas!$B$10 | H40: =-Premissas!$B$11 | I40: =-Premissas!D25 | J40: =SUM(C40:I40) | K40: =J40-C40*Premissas!$B$12 | L40: =L39+K40
A41: 37 | B41: =IF(A41<=3,Premissas!$B$28,IF(A41<=6,Premissas!$B$29,IF(A41<=9,Premissas!$B$30,IF(A41<=12,Premissas!$B$31,Premissas!$B$32)))) | C41: =Premissas!D22*B41 | D41: =-C41*Premissas!$B$7 | E41: =-C41*Premissas!$B$8 | F41: =-C41*Premissas!$B$9 | G41: =-C41*Premissas!$B$10 | H41: =-Premissas!$B$11 | I41: =-Premissas!D25 | J41: =SUM(C41:I41) | K41: =J41-C41*Premissas!$B$12 | L41: =L40+K41
...
